<?xml version="1.0" encoding="UTF-8"?>
<testng-results retried="1" ignored="1" total="7" passed="1" failed="3" skipped="1">
  <reporter-output>
  </reporter-output>
  <suite started-at="2024-08-27T13:11:54 IST" name="Suite" finished-at="2024-08-27T13:12:30 IST" duration-ms="36493">
    <groups>
      <group name="ErrorHandling">
        <method signature="ErrorValidationsTest.loginErrorValidation()[pri:0, instance:extentia.tests.ErrorValidationsTest@1df8b5b8]" name="loginErrorValidation" class="extentia.tests.ErrorValidationsTest"/>
      </group> <!-- ErrorHandling -->
      <group name="Purchase">
        <method signature="SubmitOrderTest.submitOrder(java.util.HashMap)[pri:0, instance:extentia.tests.SubmitOrderTest@e3b3b2f]" name="submitOrder" class="extentia.tests.SubmitOrderTest"/>
      </group> <!-- Purchase -->
    </groups>
    <test started-at="2024-08-27T13:11:54 IST" name="Erro Validations Test" finished-at="2024-08-27T13:12:28 IST" duration-ms="33767">
      <class name="extentia.tests.ErrorValidationsTest">
        <test-method is-config="true" signature="launchApplication()[pri:0, instance:extentia.tests.ErrorValidationsTest@1df8b5b8]" started-at="2024-08-27T13:11:54 IST" name="launchApplication" finished-at="2024-08-27T13:12:04 IST" duration-ms="10508" status="PASS">
          <reporter-output>
          </reporter-output>
        </test-method> <!-- launchApplication -->
        <test-method retried="true" signature="loginErrorValidation()[pri:0, instance:extentia.tests.ErrorValidationsTest@1df8b5b8]" started-at="2024-08-27T13:12:04 IST" name="loginErrorValidation" finished-at="2024-08-27T13:12:06 IST" duration-ms="1456" status="SKIP">
          <exception class="java.lang.AssertionError">
            <message>
              <![CDATA[expected [Incorrect email or password.] but found [Incorrect email  password.]]]>
            </message>
            <full-stacktrace>
              <![CDATA[java.lang.AssertionError: expected [Incorrect email or password.] but found [Incorrect email  password.]
at org.testng.Assert.fail(Assert.java:111)
at org.testng.Assert.failNotEquals(Assert.java:1578)
at org.testng.Assert.assertEqualsImpl(Assert.java:150)
at org.testng.Assert.assertEquals(Assert.java:132)
at org.testng.Assert.assertEquals(Assert.java:656)
at org.testng.Assert.assertEquals(Assert.java:666)
at extentia.tests.ErrorValidationsTest.loginErrorValidation(ErrorValidationsTest.java:28)
at java.base/jdk.internal.reflect.DirectMethodHandleAccessor.invoke(DirectMethodHandleAccessor.java:103)
at java.base/java.lang.reflect.Method.invoke(Method.java:580)
at org.testng.internal.invokers.MethodInvocationHelper.invokeMethod(MethodInvocationHelper.java:141)
at org.testng.internal.invokers.TestInvoker.invokeMethod(TestInvoker.java:686)
at org.testng.internal.invokers.TestInvoker.invokeTestMethod(TestInvoker.java:230)
at org.testng.internal.invokers.MethodRunner.runInSequence(MethodRunner.java:63)
at org.testng.internal.invokers.TestInvoker$MethodInvocationAgent.invoke(TestInvoker.java:992)
at org.testng.internal.invokers.TestInvoker.invokeTestMethods(TestInvoker.java:203)
at org.testng.internal.invokers.TestMethodWorker.invokeTestMethods(TestMethodWorker.java:154)
at org.testng.internal.invokers.TestMethodWorker.run(TestMethodWorker.java:134)
at java.base/java.util.ArrayList.forEach(ArrayList.java:1596)
at org.testng.TestRunner.privateRun(TestRunner.java:739)
at org.testng.TestRunner.run(TestRunner.java:614)
at org.testng.SuiteRunner.runTest(SuiteRunner.java:421)
at org.testng.SuiteRunner$SuiteWorker.run(SuiteRunner.java:463)
at org.testng.internal.thread.ThreadUtil.lambda$execute$0(ThreadUtil.java:64)
at java.base/java.util.concurrent.FutureTask.run(FutureTask.java:317)
at java.base/java.util.concurrent.ThreadPoolExecutor.runWorker(ThreadPoolExecutor.java:1144)
at java.base/java.util.concurrent.ThreadPoolExecutor$Worker.run(ThreadPoolExecutor.java:642)
at java.base/java.lang.Thread.run(Thread.java:1583)
]]>
            </full-stacktrace>
          </exception> <!-- java.lang.AssertionError -->
          <reporter-output>
          </reporter-output>
        </test-method> <!-- loginErrorValidation -->
        <test-method is-config="true" signature="tearDown()[pri:0, instance:extentia.tests.ErrorValidationsTest@1df8b5b8]" started-at="2024-08-27T13:12:06 IST" name="tearDown" finished-at="2024-08-27T13:12:06 IST" duration-ms="465" status="PASS">
          <reporter-output>
          </reporter-output>
        </test-method> <!-- tearDown -->
        <test-method is-config="true" signature="launchApplication()[pri:0, instance:extentia.tests.ErrorValidationsTest@1df8b5b8]" started-at="2024-08-27T13:12:06 IST" name="launchApplication" finished-at="2024-08-27T13:12:10 IST" duration-ms="3527" status="PASS">
          <reporter-output>
          </reporter-output>
        </test-method> <!-- launchApplication -->
        <test-method signature="loginErrorValidation()[pri:0, instance:extentia.tests.ErrorValidationsTest@1df8b5b8]" started-at="2024-08-27T13:12:10 IST" name="loginErrorValidation" finished-at="2024-08-27T13:12:11 IST" duration-ms="1057" status="FAIL">
          <exception class="java.lang.AssertionError">
            <message>
              <![CDATA[expected [Incorrect email or password.] but found [Incorrect email  password.]]]>
            </message>
            <full-stacktrace>
              <![CDATA[java.lang.AssertionError: expected [Incorrect email or password.] but found [Incorrect email  password.]
at org.testng.Assert.fail(Assert.java:111)
at org.testng.Assert.failNotEquals(Assert.java:1578)
at org.testng.Assert.assertEqualsImpl(Assert.java:150)
at org.testng.Assert.assertEquals(Assert.java:132)
at org.testng.Assert.assertEquals(Assert.java:656)
at org.testng.Assert.assertEquals(Assert.java:666)
at extentia.tests.ErrorValidationsTest.loginErrorValidation(ErrorValidationsTest.java:28)
at java.base/jdk.internal.reflect.DirectMethodHandleAccessor.invoke(DirectMethodHandleAccessor.java:103)
at java.base/java.lang.reflect.Method.invoke(Method.java:580)
at org.testng.internal.invokers.MethodInvocationHelper.invokeMethod(MethodInvocationHelper.java:141)
at org.testng.internal.invokers.TestInvoker.invokeMethod(TestInvoker.java:686)
at org.testng.internal.invokers.TestInvoker.retryFailed(TestInvoker.java:269)
at org.testng.internal.invokers.MethodRunner.runInSequence(MethodRunner.java:76)
at org.testng.internal.invokers.TestInvoker$MethodInvocationAgent.invoke(TestInvoker.java:992)
at org.testng.internal.invokers.TestInvoker.invokeTestMethods(TestInvoker.java:203)
at org.testng.internal.invokers.TestMethodWorker.invokeTestMethods(TestMethodWorker.java:154)
at org.testng.internal.invokers.TestMethodWorker.run(TestMethodWorker.java:134)
at java.base/java.util.ArrayList.forEach(ArrayList.java:1596)
at org.testng.TestRunner.privateRun(TestRunner.java:739)
at org.testng.TestRunner.run(TestRunner.java:614)
at org.testng.SuiteRunner.runTest(SuiteRunner.java:421)
at org.testng.SuiteRunner$SuiteWorker.run(SuiteRunner.java:463)
at org.testng.internal.thread.ThreadUtil.lambda$execute$0(ThreadUtil.java:64)
at java.base/java.util.concurrent.FutureTask.run(FutureTask.java:317)
at java.base/java.util.concurrent.ThreadPoolExecutor.runWorker(ThreadPoolExecutor.java:1144)
at java.base/java.util.concurrent.ThreadPoolExecutor$Worker.run(ThreadPoolExecutor.java:642)
at java.base/java.lang.Thread.run(Thread.java:1583)
]]>
            </full-stacktrace>
          </exception> <!-- java.lang.AssertionError -->
          <reporter-output>
          </reporter-output>
        </test-method> <!-- loginErrorValidation -->
        <test-method is-config="true" signature="tearDown()[pri:0, instance:extentia.tests.ErrorValidationsTest@1df8b5b8]" started-at="2024-08-27T13:12:11 IST" name="tearDown" finished-at="2024-08-27T13:12:12 IST" duration-ms="379" status="PASS">
          <reporter-output>
          </reporter-output>
        </test-method> <!-- tearDown -->
        <test-method is-config="true" signature="launchApplication()[pri:0, instance:extentia.tests.ErrorValidationsTest@1df8b5b8]" started-at="2024-08-27T13:12:12 IST" name="launchApplication" finished-at="2024-08-27T13:12:16 IST" duration-ms="4227" status="PASS">
          <reporter-output>
          </reporter-output>
        </test-method> <!-- launchApplication -->
        <test-method signature="productErrorValidation()[pri:0, instance:extentia.tests.ErrorValidationsTest@1df8b5b8]" started-at="2024-08-27T13:12:16 IST" name="productErrorValidation" finished-at="2024-08-27T13:12:27 IST" duration-ms="10924" status="FAIL">
          <exception class="org.openqa.selenium.TimeoutException">
            <message>
              <![CDATA[Expected condition failed: waiting for visibility of element located by By.cssSelector: .mb-3 (tried for 5 second(s) with 500 milliseconds interval)
Build info: version: '4.23.0', revision: '4df0a231af'
System info: os.name: 'Windows 11', os.arch: 'amd64', os.version: '10.0', java.version: '21.0.4'
Driver info: org.openqa.selenium.chrome.ChromeDriver
Capabilities {acceptInsecureCerts: false, browserName: chrome, browserVersion: 127.0.6533.119, chrome: {chromedriverVersion: 127.0.6533.119 (bdef6783a05..., userDataDir: C:\Users\Lenovo\AppData\Loc...}, fedcm:accounts: true, goog:chromeOptions: {debuggerAddress: localhost:50734}, networkConnectionEnabled: false, pageLoadStrategy: normal, platformName: windows, proxy: Proxy(), se:cdp: ws://localhost:50734/devtoo..., se:cdpVersion: 127.0.6533.119, setWindowRect: true, strictFileInteractability: false, timeouts: {implicit: 0, pageLoad: 300000, script: 30000}, unhandledPromptBehavior: dismiss and notify, webauthn:extension:credBlob: true, webauthn:extension:largeBlob: true, webauthn:extension:minPinLength: true, webauthn:extension:prf: true, webauthn:virtualAuthenticators: true}
Session ID: 2dc90237394558f5b2dfb691e807373a]]>
            </message>
            <full-stacktrace>
              <![CDATA[org.openqa.selenium.TimeoutException: Expected condition failed: waiting for visibility of element located by By.cssSelector: .mb-3 (tried for 5 second(s) with 500 milliseconds interval)
Build info: version: '4.23.0', revision: '4df0a231af'
System info: os.name: 'Windows 11', os.arch: 'amd64', os.version: '10.0', java.version: '21.0.4'
Driver info: org.openqa.selenium.chrome.ChromeDriver
Capabilities {acceptInsecureCerts: false, browserName: chrome, browserVersion: 127.0.6533.119, chrome: {chromedriverVersion: 127.0.6533.119 (bdef6783a05..., userDataDir: C:\Users\Lenovo\AppData\Loc...}, fedcm:accounts: true, goog:chromeOptions: {debuggerAddress: localhost:50734}, networkConnectionEnabled: false, pageLoadStrategy: normal, platformName: windows, proxy: Proxy(), se:cdp: ws://localhost:50734/devtoo..., se:cdpVersion: 127.0.6533.119, setWindowRect: true, strictFileInteractability: false, timeouts: {implicit: 0, pageLoad: 300000, script: 30000}, unhandledPromptBehavior: dismiss and notify, webauthn:extension:credBlob: true, webauthn:extension:largeBlob: true, webauthn:extension:minPinLength: true, webauthn:extension:prf: true, webauthn:virtualAuthenticators: true}
Session ID: 2dc90237394558f5b2dfb691e807373a
at org.openqa.selenium.support.ui.WebDriverWait.timeoutException(WebDriverWait.java:84)
at org.openqa.selenium.support.ui.FluentWait.until(FluentWait.java:228)
at extentia.AbstractComponents.AbstractComponents.waitForElementToAppear(AbstractComponents.java:36)
at extentia.pageObjects.ProductCatalogue.getProductList(ProductCatalogue.java:36)
at extentia.tests.ErrorValidationsTest.productErrorValidation(ErrorValidationsTest.java:38)
at java.base/jdk.internal.reflect.DirectMethodHandleAccessor.invoke(DirectMethodHandleAccessor.java:103)
at java.base/java.lang.reflect.Method.invoke(Method.java:580)
at org.testng.internal.invokers.MethodInvocationHelper.invokeMethod(MethodInvocationHelper.java:141)
at org.testng.internal.invokers.TestInvoker.invokeMethod(TestInvoker.java:686)
at org.testng.internal.invokers.TestInvoker.invokeTestMethod(TestInvoker.java:230)
at org.testng.internal.invokers.MethodRunner.runInSequence(MethodRunner.java:63)
at org.testng.internal.invokers.TestInvoker$MethodInvocationAgent.invoke(TestInvoker.java:992)
at org.testng.internal.invokers.TestInvoker.invokeTestMethods(TestInvoker.java:203)
at org.testng.internal.invokers.TestMethodWorker.invokeTestMethods(TestMethodWorker.java:154)
at org.testng.internal.invokers.TestMethodWorker.run(TestMethodWorker.java:134)
at java.base/java.util.ArrayList.forEach(ArrayList.java:1596)
at org.testng.TestRunner.privateRun(TestRunner.java:739)
at org.testng.TestRunner.run(TestRunner.java:614)
at org.testng.SuiteRunner.runTest(SuiteRunner.java:421)
at org.testng.SuiteRunner$SuiteWorker.run(SuiteRunner.java:463)
at org.testng.internal.thread.ThreadUtil.lambda$execute$0(ThreadUtil.java:64)
at java.base/java.util.concurrent.FutureTask.run(FutureTask.java:317)
at java.base/java.util.concurrent.ThreadPoolExecutor.runWorker(ThreadPoolExecutor.java:1144)
at java.base/java.util.concurrent.ThreadPoolExecutor$Worker.run(ThreadPoolExecutor.java:642)
at java.base/java.lang.Thread.run(Thread.java:1583)
]]>
            </full-stacktrace>
          </exception> <!-- org.openqa.selenium.TimeoutException -->
          <reporter-output>
          </reporter-output>
        </test-method> <!-- productErrorValidation -->
        <test-method is-config="true" signature="tearDown()[pri:0, instance:extentia.tests.ErrorValidationsTest@1df8b5b8]" started-at="2024-08-27T13:12:27 IST" name="tearDown" finished-at="2024-08-27T13:12:28 IST" duration-ms="266" status="PASS">
          <reporter-output>
          </reporter-output>
        </test-method> <!-- tearDown -->
      </class> <!-- extentia.tests.ErrorValidationsTest -->
    </test> <!-- Erro Validations Test -->
    <test started-at="2024-08-27T13:11:54 IST" name="Submit Order Test" finished-at="2024-08-27T13:12:30 IST" duration-ms="36493">
      <class name="extentia.tests.SubmitOrderTest">
        <test-method is-config="true" signature="launchApplication()[pri:0, instance:extentia.tests.SubmitOrderTest@e3b3b2f]" started-at="2024-08-27T13:11:54 IST" name="launchApplication" finished-at="2024-08-27T13:12:03 IST" duration-ms="8609" status="PASS">
          <reporter-output>
          </reporter-output>
        </test-method> <!-- launchApplication -->
        <test-method signature="submitOrder(java.util.HashMap)[pri:0, instance:extentia.tests.SubmitOrderTest@e3b3b2f]" started-at="2024-08-27T13:12:03 IST" name="submitOrder" data-provider="getData" finished-at="2024-08-27T13:12:11 IST" duration-ms="8484" status="PASS">
          <params>
            <param index="0">
              <value>
                <![CDATA[{password=Gmail123456@, product=ZARA COAT 3, email=Faisal1@gmail.com}]]>
              </value>
            </param>
          </params>
          <reporter-output>
          </reporter-output>
        </test-method> <!-- submitOrder -->
        <test-method is-config="true" signature="tearDown()[pri:0, instance:extentia.tests.SubmitOrderTest@e3b3b2f]" started-at="2024-08-27T13:12:11 IST" name="tearDown" finished-at="2024-08-27T13:12:12 IST" duration-ms="446" status="PASS">
          <reporter-output>
          </reporter-output>
        </test-method> <!-- tearDown -->
        <test-method is-config="true" signature="launchApplication()[pri:0, instance:extentia.tests.SubmitOrderTest@e3b3b2f]" started-at="2024-08-27T13:12:12 IST" name="launchApplication" finished-at="2024-08-27T13:12:14 IST" duration-ms="2628" status="PASS">
          <reporter-output>
          </reporter-output>
        </test-method> <!-- launchApplication -->
        <test-method signature="submitOrder(java.util.HashMap)[pri:0, instance:extentia.tests.SubmitOrderTest@e3b3b2f]" started-at="2024-08-27T13:12:14 IST" name="submitOrder" data-provider="getData" finished-at="2024-08-27T13:12:30 IST" duration-ms="15562" status="FAIL">
          <params>
            <param index="0">
              <value>
                <![CDATA[{password=Gmail123456@, product=ADDIDAS ORIGINAL, email=Faisal1@gmail.com}]]>
              </value>
            </param>
          </params>
          <exception class="java.lang.AssertionError">
            <message>
              <![CDATA[expected [true] but found [false]]]>
            </message>
            <full-stacktrace>
              <![CDATA[java.lang.AssertionError: expected [true] but found [false]
at org.testng.Assert.fail(Assert.java:111)
at org.testng.Assert.failNotEquals(Assert.java:1578)
at org.testng.Assert.assertTrue(Assert.java:57)
at org.testng.Assert.assertTrue(Assert.java:67)
at extentia.tests.SubmitOrderTest.submitOrder(SubmitOrderTest.java:51)
at java.base/jdk.internal.reflect.DirectMethodHandleAccessor.invoke(DirectMethodHandleAccessor.java:103)
at java.base/java.lang.reflect.Method.invoke(Method.java:580)
at org.testng.internal.invokers.MethodInvocationHelper.invokeMethod(MethodInvocationHelper.java:141)
at org.testng.internal.invokers.TestInvoker.invokeMethod(TestInvoker.java:686)
at org.testng.internal.invokers.TestInvoker.invokeTestMethod(TestInvoker.java:230)
at org.testng.internal.invokers.MethodRunner.runInSequence(MethodRunner.java:63)
at org.testng.internal.invokers.TestInvoker$MethodInvocationAgent.invoke(TestInvoker.java:992)
at org.testng.internal.invokers.TestInvoker.invokeTestMethods(TestInvoker.java:203)
at org.testng.internal.invokers.TestMethodWorker.invokeTestMethods(TestMethodWorker.java:154)
at org.testng.internal.invokers.TestMethodWorker.run(TestMethodWorker.java:134)
at java.base/java.util.ArrayList.forEach(ArrayList.java:1596)
at org.testng.TestRunner.privateRun(TestRunner.java:739)
at org.testng.TestRunner.run(TestRunner.java:614)
at org.testng.SuiteRunner.runTest(SuiteRunner.java:421)
at org.testng.SuiteRunner$SuiteWorker.run(SuiteRunner.java:463)
at org.testng.internal.thread.ThreadUtil.lambda$execute$0(ThreadUtil.java:64)
at java.base/java.util.concurrent.FutureTask.run(FutureTask.java:317)
at java.base/java.util.concurrent.ThreadPoolExecutor.runWorker(ThreadPoolExecutor.java:1144)
at java.base/java.util.concurrent.ThreadPoolExecutor$Worker.run(ThreadPoolExecutor.java:642)
at java.base/java.lang.Thread.run(Thread.java:1583)
]]>
            </full-stacktrace>
          </exception> <!-- java.lang.AssertionError -->
          <reporter-output>
          </reporter-output>
        </test-method> <!-- submitOrder -->
        <test-method is-config="true" signature="tearDown()[pri:0, instance:extentia.tests.SubmitOrderTest@e3b3b2f]" started-at="2024-08-27T13:12:30 IST" name="tearDown" finished-at="2024-08-27T13:12:30 IST" duration-ms="192" status="PASS">
          <reporter-output>
          </reporter-output>
        </test-method> <!-- tearDown -->
        <test-method signature="orderHistoryTest()[pri:0, instance:extentia.tests.SubmitOrderTest@e3b3b2f]" started-at="2024-08-27T13:12:30 IST" name="orderHistoryTest" finished-at="2024-08-27T13:12:30 IST" depends-on-methods="extentia.tests.SubmitOrderTest.submitOrder" duration-ms="0" status="SKIP">
          <exception class="java.lang.Throwable">
            <message>
              <![CDATA[Method extentia.tests.SubmitOrderTest.orderHistoryTest() on instance extentia.tests.SubmitOrderTest@e3b3b2f depends on not successfully finished methods 
[extentia.tests.SubmitOrderTest.submitOrder() on instance extentia.tests.SubmitOrderTest@e3b3b2f]]]>
            </message>
            <full-stacktrace>
              <![CDATA[java.lang.Throwable: Method extentia.tests.SubmitOrderTest.orderHistoryTest() on instance extentia.tests.SubmitOrderTest@e3b3b2f depends on not successfully finished methods 
[extentia.tests.SubmitOrderTest.submitOrder() on instance extentia.tests.SubmitOrderTest@e3b3b2f]
at org.testng.internal.invokers.TestInvoker.invokeTestMethods(TestInvoker.java:159)
at org.testng.internal.invokers.TestMethodWorker.invokeTestMethods(TestMethodWorker.java:154)
at org.testng.internal.invokers.TestMethodWorker.run(TestMethodWorker.java:134)
at java.base/java.util.ArrayList.forEach(ArrayList.java:1596)
at org.testng.TestRunner.privateRun(TestRunner.java:739)
at org.testng.TestRunner.run(TestRunner.java:614)
at org.testng.SuiteRunner.runTest(SuiteRunner.java:421)
at org.testng.SuiteRunner$SuiteWorker.run(SuiteRunner.java:463)
at org.testng.internal.thread.ThreadUtil.lambda$execute$0(ThreadUtil.java:64)
at java.base/java.util.concurrent.FutureTask.run(FutureTask.java:317)
at java.base/java.util.concurrent.ThreadPoolExecutor.runWorker(ThreadPoolExecutor.java:1144)
at java.base/java.util.concurrent.ThreadPoolExecutor$Worker.run(ThreadPoolExecutor.java:642)
at java.base/java.lang.Thread.run(Thread.java:1583)
]]>
            </full-stacktrace>
          </exception> <!-- java.lang.Throwable -->
          <reporter-output>
          </reporter-output>
        </test-method> <!-- orderHistoryTest -->
      </class> <!-- extentia.tests.SubmitOrderTest -->
    </test> <!-- Submit Order Test -->
  </suite> <!-- Suite -->
</testng-results>
